Workbook
Name AD21AF348: #REF!
Name AD21AF348: #REF!

Sheet ICSE
A1: Paper ID | B1: Paper Title | C1: Year | D1: Successfully passed AE | E1: Artifacts Available badge | F1: Functional - Artifacts Evaluated badge | G1: Reusable - Artifacts Evaluated badge | H1: Results Replicated - Results Validated badge | I1: Results Reproduced - Results Validated badge | J1: Other badge | K1: Artifact link | L1: Footnote | M1: References | N1: Introduction | O1: Conclusion | P1: Highlight | Q1: Specific section or subsection | R1: Other Place | S1: Where is talking about the link? | T1: Artifact link(s) | U1: ="All artifact links whitout repetition - column "&SUBSTITUTE(ADDRESS(ROW(T1),COLUMN(T1),4),1,"")&" for artifact sharing (without real link)" -> All artifact links whitout repetition - column T for artifact sharing (without real link) | V1: Publicly available | W1: Not available | X1: Restrict access | Y1: No links | Z1: ="Status of the links in 02/24/2024 - "&SUBSTITUTE(ADDRESS(ROW(U1),COLUMN(U1),4),1,"") -> Status of the links in 02/24/2024 - U | AA1: # of different links | AB1: University domain | AC1: unique identifier | AD1: Is there a statement? | AE1: Statements for non-disclosure or partial disclosure of the research artifacts | AF1: Statements 1 | AG1: Statements 2 | AH1: Statements 3 | AI1: ="All statement labels "&SUBSTITUTE(ADDRESS(ROW(AF1),COLUMN(AF1),4),1,"")&" + "&SUBSTITUTE(ADDRESS(ROW(AG1),COLUMN(AG1),4),1,"")&" + "&SUBSTITUTE(ADDRESS(ROW(AH1),COLUMN(AH1),4),1,"") -> All statement labels AF + AG + AH | AJ1: ="Link and statement analysis "&SUBSTITUTE(ADDRESS(ROW(K1),COLUMN(K1),4),1,"")&" and "&SUBSTITUTE(ADDRESS(ROW(AD1),COLUMN(AD1),4),1,"") -> Link and statement analysis K and AD | AK1: Paper download | AL1: Track | AM1: Paper ID
A2: 1844 | B2: Cowboys, ankle sprains, and keepers of quality: how is video game development different from software development? | C2: 2014 | D2: No | E2: - | F2: - | G2: - | H2: - | I2: - | J2: - | K2: Yes | L2: Yes | M2: Yes | N2: No | O2: No | P2: No | Q2: No | R2: Yes | S2: - FN 1 - 3. METHODOLOGY - [38] 4. RESULTS | T2: http://people.engr.ncsu.edu/ermurph3/experiments/Games.pdf > Microsoft Research (MSR-TR-2014-24) - real link: https://www.microsoft.com/en-us/research/wp-content/uploads/2016/02/MSR-TR-2014-24.pdf | U2: http://people.engr.ncsu.edu/ermurph3/experiments/Games.pdf Microsoft Research (MSR-TR-2014-24) - real link: https://www.microsoft.com/en-us/research/wp-content/uploads/2016/02/MSR-TR-2014-24.pdf | V2: =IF(lenb(SUBSTITUTE($Z2,V$1&" (1)",""))<lenb($Z2),1,IF(lenb(SUBSTITUTE($Z2,V$1&" (2)",""))<lenb($Z2),2,IF(lenb(SUBSTITUTE($Z2,V$1&" (3)",""))<lenb($Z2),3,IF(lenb(SUBSTITUTE($Z2,V$1&" (4)",""))<lenb($Z2),4,IF(lenb(SUBSTITUTE($Z2,V$1&" (5)",""))<lenb($Z2),5,IF(lenb(SUBSTITUTE($Z2,V$1&" (6)",""))<lenb($Z2),6,IF(lenb(SUBSTITUTE($Z2,V$1&" (7)",""))<lenb($Z2),1,IF(lenb(SUBSTITUTE($Z2,V$1&" (8)",""))<lenb($Z2),8,IF(lenb(SUBSTITUTE($Z2,V$1&" (9)",""))<lenb($Z2),9,IF(lenb(SUBSTITUTE($Z2,V$1&" (10)",""))<lenb($Z2),10,IF(lenb(SUBSTITUTE($Z2,V$1,""))<lenb($Z2),"ERROR",IF($Z2=$Y$1,"-",0)))))))))))) -> 1 | W2: =IF(lenb(SUBSTITUTE($Z2,W$1&" (1)",""))<lenb($Z2),1,IF(lenb(SUBSTITUTE($Z2,W$1&" (2)",""))<lenb($Z2),2,IF(lenb(SUBSTITUTE($Z2,W$1&" (3)",""))<lenb($Z2),3,IF(lenb(SUBSTITUTE($Z2,W$1&" (4)",""))<lenb($Z2),4,IF(lenb(SUBSTITUTE($Z2,W$1&" (5)",""))<lenb($Z2),5,IF(lenb(SUBSTITUTE($Z2,W$1&" (6)",""))<lenb($Z2),6,IF(lenb(SUBSTITUTE($Z2,W$1&" (7)",""))<lenb($Z2),1,IF(lenb(SUBSTITUTE($Z2,W$1&" (8)",""))<lenb($Z2),8,IF(lenb(SUBSTITUTE($Z2,W$1&" (9)",""))<lenb($Z2),9,IF(lenb(SUBSTITUTE($Z2,W$1&" (10)",""))<lenb($Z2),10,IF(lenb(SUBSTITUTE($Z2,W$1,""))<lenb($Z2),"ERROR",IF($Z2=$Y$1,"-",0)))))))))))) -> 1 | X2: =IF(lenb(SUBSTITUTE($Z2,X$1&" (1)",""))<lenb($Z2),1,IF(lenb(SUBSTITUTE($Z2,X$1&" (2)",""))<lenb($Z2),2,IF(lenb(SUBSTITUTE($Z2,X$1&" (3)",""))<lenb($Z2),3,IF(lenb(SUBSTITUTE($Z2,X$1&" (4)",""))<lenb($Z2),4,IF(lenb(SUBSTITUTE($Z2,X$1&" (5)",""))<lenb($Z2),5,IF(lenb(SUBSTITUTE($Z2,X$1&" (6)",""))<lenb($Z2),6,IF(lenb(SUBSTITUTE($Z2,X$1&" (7)",""))<lenb($Z2),1,IF(lenb(SUBSTITUTE($Z2,X$1&" (8)",""))<lenb($Z2),8,IF(lenb(SUBSTITUTE($Z2,X$1&" (9)",""))<lenb($Z2),9,IF(lenb(SUBSTITUTE($Z2,X$1&" (10)",""))<lenb($Z2),10,IF(lenb(SUBSTITUTE($Z2,X$1,""))<lenb($Z2),"ERROR",IF($Z2=$Y$1,"-",0)))))))))))) -> 0 | Y2: =IF(Z2=Y$1,1,"-") -> - | Z2: Not available (1) - Broken link. Publicly available (1) | AA2: =ifs(U2="","",U2="-",0,U2="Erro",0,U2<>"",LEN(U2)-LEN(SUBSTITUTE(U2,CHAR(10),""))+1) -> 2 | AB2: =COUNTIFS(Links!B:B,"ICSE",Links!C:C,A2,Links!AD:AD,1) -> 1 | AC2: No | AD2: =ifs(AE2="None.","No",AE2="-","No",AND(AE2<>"None.",AE2<>"-"),"Yes") -> No | AE2: - | AF2: ---- | AG2: ---- | AH2: ---- | AI2: =IF(AH2="----",IF(AG2="----",IF(AF2="----","----",AF2),AF2&CHAR(10)&AG2),AF2&CHAR(10)&AG2&CHAR(10)&AH2) -> ---- | AJ2: =IFERROR( if(and(K2="Yes",AD2="No"),"Paper has link but no statement", if(and(K2="No",AD2="No"),"Paper has no link and no statement", if(and(K2="Yes",AD2="Yes"),"Paper has link and statement", if(and(K2="No",AD2="Yes"),"Paper has no link but has statement","")))),"") -> Paper has link but no statement | AK2: 45035 | AL2: Technical | AM2: ="[IP"&TEXT(A2,"0000")&"]" -> [IP1844]
A3: 1845 | B3: Analyze this! 145 questions for data scientists in software engineering | C3: 2014 | D3: Yes | E3: No | F3: No | G3: No | H3: Yes | I3: No | J3: - | K3: Yes | L3: No | M3: Yes | N3: Yes | O3: Yes | P3: No | Q3: No | R3: Yes | S3: [11] - 1. INTRODUCTION - 3. METHODOLOGY * (4x) - 6. CONCLUSION | T3: http://aka.ms/145Questions | U3: http://aka.ms/145Questions | V3: =IF(lenb(SUBSTITUTE($Z3,V$1&" (1)",""))<lenb($Z3),1,IF(lenb(SUBSTITUTE($Z3,V$1&" (2)",""))<lenb($Z3),2,IF(lenb(SUBSTITUTE($Z3,V$1&" (3)",""))<lenb($Z3),3,IF(lenb(SUBSTITUTE($Z3,V$1&" (4)",""))<lenb($Z3),4,IF(lenb(SUBSTITUTE($Z3,V$1&" (5)",""))<lenb($Z3),5,IF(lenb(SUBSTITUTE($Z3,V$1&" (6)",""))<lenb($Z3),6,IF(lenb(SUBSTITUTE($Z3,V$1&" (7)",""))<lenb($Z3),1,IF(lenb(SUBSTITUTE($Z3,V$1&" (8)",""))<lenb($Z3),8,IF(lenb(SUBSTITUTE($Z3,V$1&" (9)",""))<lenb($Z3),9,IF(lenb(SUBSTITUTE($Z3,V$1&" (10)",""))<lenb($Z3),10,IF(lenb(SUBSTITUTE($Z3,V$1,""))<lenb($Z3),"ERROR",IF($Z3=$Y$1,"-",0)))))))))))) -> 0 | W3: =IF(lenb(SUBSTITUTE($Z3,W$1&" (1)",""))<lenb($Z3),1,IF(lenb(SUBSTITUTE($Z3,W$1&" (2)",""))<lenb($Z3),2,IF(lenb(SUBSTITUTE($Z3,W$1&" (3)",""))<lenb($Z3),3,IF(lenb(SUBSTITUTE($Z3,W$1&" (4)",""))<lenb($Z3),4,IF(lenb(SUBSTITUTE($Z3,W$1&" (5)",""))<lenb($Z3),5,IF(lenb(SUBSTITUTE($Z3,W$1&" (6)",""))<lenb($Z3),6,IF(lenb(SUBSTITUTE($Z3,W$1&" (7)",""))<lenb($Z3),1,IF(lenb(SUBSTITUTE($Z3,W$1&" (8)",""))<lenb($Z3),8,IF(lenb(SUBSTITUTE($Z3,W$1&" (9)",""))<lenb($Z3),9,IF(lenb(SUBSTITUTE($Z3,W$1&" (10)",""))<lenb($Z3),10,IF(lenb(SUBSTITUTE($Z3,W$1,""))<lenb($Z3),"ERROR",IF($Z3=$Y$1,"-",0)))))))))))) -> 1 | X3: =IF(lenb(SUBSTITUTE($Z3,X$1&" (1)",""))<lenb($Z3),1,IF(lenb(SUBSTITUTE($Z3,X$1&" (2)",""))<lenb($Z3),2,IF(lenb(SUBSTITUTE($Z3,X$1&" (3)",""))<lenb($Z3),3,IF(lenb(SUBSTITUTE($Z3,X$1&" (4)",""))<lenb($Z3),4,IF(lenb(SUBSTITUTE($Z3,X$1&" (5)",""))<lenb($Z3),5,IF(lenb(SUBSTITUTE($Z3,X$1&" (6)",""))<lenb($Z3),6,IF(lenb(SUBSTITUTE($Z3,X$1&" (7)",""))<lenb($Z3),1,IF(lenb(SUBSTITUTE($Z3,X$1&" (8)",""))<lenb($Z3),8,IF(lenb(SUBSTITUTE($Z3,X$1&" (9)",""))<lenb($Z3),9,IF(lenb(SUBSTITUTE($Z3,X$1&" (10)",""))<lenb($Z3),10,IF(lenb(SUBSTITUTE($Z3,X$1,""))<lenb($Z3),"ERROR",IF($Z3=$Y$1,"-",0)))))))))))) -> 0 | Y3: =IF(Z3=Y$1,1,"-") -> - | Z3: Not available (1) - Broken link. | AA3: =ifs(U3="","",U3="-",0,U3="Erro",0,U3<>"",LEN(U3)-LEN(SUBSTITUTE(U3,CHAR(10),""))+1) -> 1 | AB3: =COUNTIFS(Links!B:B,"ICSE",Links!C:C,A3,Links!AD:AD,1) -> 0 | AC3: No | AD3: =ifs(AE3="None.","No",AE3="-","No",AND(AE3<>"None.",AE3<>"-"),"Yes") -> No | AE3: - | AF3: ---- | AG3: ---- | AH3: ---- | AI3: =IF(AH3="----",IF(AG3="----",IF(AF3="----","----",AF3),AF3&CHAR(10)&AG3),AF3&CHAR(10)&AG3&CHAR(10)&AH3) -> ---- | AJ3: =IFERROR( if(and(K3="Yes",AD3="No"),"Paper has link but no statement", if(and(K3="No",AD3="No"),"Paper has no link and no statement", if(and(K3="Yes",AD3="Yes"),"Paper has link and statement", if(and(K3="No",AD3="Yes"),"Paper has no link but has statement","")))),"") -> Paper has link but no statement | AK3: 45035 | AL3: Technical | AM3: ="[IP"&TEXT(A3,"0000")&"]" -> [IP1845]
A4: 1846 | B4: The dimensions of software engineering success | C4: 2014 | D4: No | E4: - | F4: - | G4: - | H4: - | I4: - | J4: - | K4: No | L4: - | M4: - | N4: - | O4: - | P4: - | Q4: - | R4: - | S4: - | T4: - | U4: - | V4: =IF(lenb(SUBSTITUTE($Z4,V$1&" (1)",""))<lenb($Z4),1,IF(lenb(SUBSTITUTE($Z4,V$1&" (2)",""))<lenb($Z4),2,IF(lenb(SUBSTITUTE($Z4,V$1&" (3)",""))<lenb($Z4),3,IF(lenb(SUBSTITUTE($Z4,V$1&" (4)",""))<lenb($Z4),4,IF(lenb(SUBSTITUTE($Z4,V$1&" (5)",""))<lenb($Z4),5,IF(lenb(SUBSTITUTE($Z4,V$1&" (6)",""))<lenb($Z4),6,IF(lenb(SUBSTITUTE($Z4,V$1&" (7)",""))<lenb($Z4),1,IF(lenb(SUBSTITUTE($Z4,V$1&" (8)",""))<lenb($Z4),8,IF(lenb(SUBSTITUTE($Z4,V$1&" (9)",""))<lenb($Z4),9,IF(lenb(SUBSTITUTE($Z4,V$1&" (10)",""))<lenb($Z4),10,IF(lenb(SUBSTITUTE($Z4,V$1,""))<lenb($Z4),"ERROR",IF($Z4=$Y$1,"-",0)))))))))))) -> - | W4: =IF(lenb(SUBSTITUTE($Z4,W$1&" (1)",""))<lenb($Z4),1,IF(lenb(SUBSTITUTE($Z4,W$1&" (2)",""))<lenb($Z4),2,IF(lenb(SUBSTITUTE($Z4,W$1&" (3)",""))<lenb($Z4),3,IF(lenb(SUBSTITUTE($Z4,W$1&" (4)",""))<lenb($Z4),4,IF(lenb(SUBSTITUTE($Z4,W$1&" (5)",""))<lenb($Z4),5,IF(lenb(SUBSTITUTE($Z4,W$1&" (6)",""))<lenb($Z4),6,IF(lenb(SUBSTITUTE($Z4,W$1&" (7)",""))<lenb($Z4),1,IF(lenb(SUBSTITUTE($Z4,W$1&" (8)",""))<lenb($Z4),8,IF(lenb(SUBSTITUTE($Z4,W$1&" (9)",""))<lenb($Z4),9,IF(lenb(SUBSTITUTE($Z4,W$1&" (10)",""))<lenb($Z4),10,IF(lenb(SUBSTITUTE($Z4,W$1,""))<lenb($Z4),"ERROR",IF($Z4=$Y$1,"-",0)))))))))))) -> - | X4: =IF(lenb(SUBSTITUTE($Z4,X$1&" (1)",""))<lenb($Z4),1,IF(lenb(SUBSTITUTE($Z4,X$1&" (2)",""))<lenb($Z4),2,IF(lenb(SUBSTITUTE($Z4,X$1&" (3)",""))<lenb($Z4),3,IF(lenb(SUBSTITUTE($Z4,X$1&" (4)",""))<lenb($Z4),4,IF(lenb(SUBSTITUTE($Z4,X$1&" (5)",""))<lenb($Z4),5,IF(lenb(SUBSTITUTE($Z4,X$1&" (6)",""))<lenb($Z4),6,IF(lenb(SUBSTITUTE($Z4,X$1&" (7)",""))<lenb($Z4),1,IF(lenb(SUBSTITUTE($Z4,X$1&" (8)",""))<lenb($Z4),8,IF(lenb(SUBSTITUTE($Z4,X$1&" (9)",""))<lenb($Z4),9,IF(lenb(SUBSTITUTE($Z4,X$1&" (10)",""))<lenb($Z4),10,IF(lenb(SUBSTITUTE($Z4,X$1,""))<lenb($Z4),"ERROR",IF($Z4=$Y$1,"-",0)))))))))))) -> - | Y4: =IF(Z4=Y$1,1,"-") -> 1 | Z4: No links | AA4: =ifs(U4="","",U4="-",0,U4="Erro",0,U4<>"",LEN(U4)-LEN(SUBSTITUTE(U4,CHAR(10),""))+1) -> 0 | AB4: =COUNTIFS(Links!B:B,"ICSE",Links!C:C,A4,Links!AD:AD,1) -> 0 | AC4: - | AD4: =ifs(AE4="None.","No",AE4="-","No",AND(AE4<>"None.",AE4<>"-"),"Yes") -> No | AE4: - | AF4: ---- | AG4: ---- | AH4: ---- | AI4: =IF(AH4="----",IF(AG4="----",IF(AF4="----","----",AF4),AF4&CHAR(10)&AG4),AF4&CHAR(10)&AG4&CHAR(10)&AH4) -> ---- | AJ4: =IFERROR( if(and(K4="Yes",AD4="No"),"Paper has link but no statement", if(and(K4="No",AD4="No"),"Paper has no link and no statement", if(and(K4="Yes",AD4="Yes"),"Paper has link and statement", if(and(K4="No",AD4="Yes"),"Paper has no link but has statement","")))),"") -> Paper has no link and no statement | AK4: 45035 | AL4: Technical | AM4: ="[IP"&TEXT(A4,"0000")&"]" -> [IP1846]
A5: 1847 | B5: How do professionals perceive legacy systems and software modernization? | C5: 2014 | D5: No | E5: - | F5: - | G5: - | H5: - | I5: - | J5: - | K5: Yes | L5: Yes | M5: Yes | N5: No | O5: No | P5: No | Q5: No | R5: Yes | S5: - FN 2 - 2. STUDY DESIGN - FN 3 - 4. DISCUSSION - [6] 2. STUDY DESIGN | T5: http://www.servicifi.org > TR UU-CS-2014-004 - real link: https://www.cs.uu.nl/research/techreps/UU-CS-2014-004.html | U5: http://www.servicifi.org TR UU-CS-2014-004 - real link: https://www.cs.uu.nl/research/techreps/UU-CS-2014-004.html | V5: =IF(lenb(SUBSTITUTE($Z5,V$1&" (1)",""))<lenb($Z5),1,IF(lenb(SUBSTITUTE($Z5,V$1&" (2)",""))<lenb($Z5),2,IF(lenb(SUBSTITUTE($Z5,V$1&" (3)",""))<lenb($Z5),3,IF(lenb(SUBSTITUTE($Z5,V$1&" (4)",""))<lenb($Z5),4,IF(lenb(SUBSTITUTE($Z5,V$1&" (5)",""))<lenb($Z5),5,IF(lenb(SUBSTITUTE($Z5,V$1&" (6)",""))<lenb($Z5),6,IF(lenb(SUBSTITUTE($Z5,V$1&" (7)",""))<lenb($Z5),1,IF(lenb(SUBSTITUTE($Z5,V$1&" (8)",""))<lenb($Z5),8,IF(lenb(SUBSTITUTE($Z5,V$1&" (9)",""))<lenb($Z5),9,IF(lenb(SUBSTITUTE($Z5,V$1&" (10)",""))<lenb($Z5),10,IF(lenb(SUBSTITUTE($Z5,V$1,""))<lenb($Z5),"ERROR",IF($Z5=$Y$1,"-",0)))))))))))) -> 1 | W5: =IF(lenb(SUBSTITUTE($Z5,W$1&" (1)",""))<lenb($Z5),1,IF(lenb(SUBSTITUTE($Z5,W$1&" (2)",""))<lenb($Z5),2,IF(lenb(SUBSTITUTE($Z5,W$1&" (3)",""))<lenb($Z5),3,IF(lenb(SUBSTITUTE($Z5,W$1&" (4)",""))<lenb($Z5),4,IF(lenb(SUBSTITUTE($Z5,W$1&" (5)",""))<lenb($Z5),5,IF(lenb(SUBSTITUTE($Z5,W$1&" (6)",""))<lenb($Z5),6,IF(lenb(SUBSTITUTE($Z5,W$1&" (7)",""))<lenb($Z5),1,IF(lenb(SUBSTITUTE($Z5,W$1&" (8)",""))<lenb($Z5),8,IF(lenb(SUBSTITUTE($Z5,W$1&" (9)",""))<lenb($Z5),9,IF(lenb(SUBSTITUTE($Z5,W$1&" (10)",""))<lenb($Z5),10,IF(lenb(SUBSTITUTE($Z5,W$1,""))<lenb($Z5),"ERROR",IF($Z5=$Y$1,"-",0)))))))))))) -> 1 | X5: =IF(lenb(SUBSTITUTE($Z5,X$1&" (1)",""))<lenb($Z5),1,IF(lenb(SUBSTITUTE($Z5,X$1&" (2)",""))<lenb($Z5),2,IF(lenb(SUBSTITUTE($Z5,X$1&" (3)",""))<lenb($Z5),3,IF(lenb(SUBSTITUTE($Z5,X$1&" (4)",""))<lenb($Z5),4,IF(lenb(SUBSTITUTE($Z5,X$1&" (5)",""))<lenb($Z5),5,IF(lenb(SUBSTITUTE($Z5,X$1&" (6)",""))<lenb($Z5),6,IF(lenb(SUBSTITUTE($Z5,X$1&" (7)",""))<lenb($Z5),1,IF(lenb(SUBSTITUTE($Z5,X$1&" (8)",""))<lenb($Z5),8,IF(lenb(SUBSTITUTE($Z5,X$1&" (9)",""))<lenb($Z5),9,IF(lenb(SUBSTITUTE($Z5,X$1&" (10)",""))<lenb($Z5),10,IF(lenb(SUBSTITUTE($Z5,X$1,""))<lenb($Z5),"ERROR",IF($Z5=$Y$1,"-",0)))))))))))) -> 0 | Y5: =IF(Z5=Y$1,1,"-") -> - | Z5: Not available (1) - Broken link. Publicly available (1) | AA5: =ifs(U5="","",U5="-",0,U5="Erro",0,U5<>"",LEN(U5)-LEN(SUBSTITUTE(U5,CHAR(10),""))+1) -> 2 | AB5: =COUNTIFS(Links!B:B,"ICSE",Links!C:C,A5,Links!AD:AD,1) -> 1 | AC5: No | AD5: =ifs(AE5="None.","No",AE5="-","No",AND(AE5<>"None.",AE5<>"-"),"Yes") -> No | AE5: - | AF5: ---- | AG5: ---- | AH5: ---- | AI5: =IF(AH5="----",IF(AG5="----",IF(AF5="----","----",AF5),AF5&CHAR(10)&AG5),AF5&CHAR(10)&AG5&CHAR(10)&AH5) -> ---- | AJ5: =IFERROR( if(and(K5="Yes",AD5="No"),"Paper has link but no statement", if(and(K5="No",AD5="No"),"Paper has no link and no statement", if(and(K5="Yes",AD5="Yes"),"Paper has link and statement", if(and(K5="No",AD5="Yes"),"Paper has no link but has statement","")))),"") -> Paper has link but no statement | AK5: 45035 | AL5: Technical | AM5: ="[IP"&TEXT(A5,"0000")&"]" -> [IP1847]
A6: 1848 | B6: SimRT: an automated framework to support regression testing for data races | C6: 2014 | D6: No | E6: - | F6: - | G6: - | H6: - | I6: - | J6: - | K6: No | L6: - | M6: - | N6: - | O6: - | P6: - | Q6: - | R6: - | S6: - | T6: - | U6: - | V6: =IF(lenb(SUBSTITUTE($Z6,V$1&" (1)",""))<lenb($Z6),1,IF(lenb(SUBSTITUTE($Z6,V$1&" (2)",""))<lenb($Z6),2,IF(lenb(SUBSTITUTE($Z6,V$1&" (3)",""))<lenb($Z6),3,IF(lenb(SUBSTITUTE($Z6,V$1&" (4)",""))<lenb($Z6),4,IF(lenb(SUBSTITUTE($Z6,V$1&" (5)",""))<lenb($Z6),5,IF(lenb(SUBSTITUTE($Z6,V$1&" (6)",""))<lenb($Z6),6,IF(lenb(SUBSTITUTE($Z6,V$1&" (7)",""))<lenb($Z6),1,IF(lenb(SUBSTITUTE($Z6,V$1&" (8)",""))<lenb($Z6),8,IF(lenb(SUBSTITUTE($Z6,V$1&" (9)",""))<lenb($Z6),9,IF(lenb(SUBSTITUTE($Z6,V$1&" (10)",""))<lenb($Z6),10,IF(lenb(SUBSTITUTE($Z6,V$1,""))<lenb($Z6),"ERROR",IF($Z6=$Y$1,"-",0)))))))))))) -> - | W6: =IF(lenb(SUBSTITUTE($Z6,W$1&" (1)",""))<lenb($Z6),1,IF(lenb(SUBSTITUTE($Z6,W$1&" (2)",""))<lenb($Z6),2,IF(lenb(SUBSTITUTE($Z6,W$1&" (3)",""))<lenb($Z6),3,IF(lenb(SUBSTITUTE($Z6,W$1&" (4)",""))<lenb($Z6),4,IF(lenb(SUBSTITUTE($Z6,W$1&" (5)",""))<lenb($Z6),5,IF(lenb(SUBSTITUTE($Z6,W$1&" (6)",""))<lenb($Z6),6,IF(lenb(SUBSTITUTE($Z6,W$1&" (7)",""))<lenb($Z6),1,IF(lenb(SUBSTITUTE($Z6,W$1&" (8)",""))<lenb($Z6),8,IF(lenb(SUBSTITUTE($Z6,W$1&" (9)",""))<lenb($Z6),9,IF(lenb(SUBSTITUTE($Z6,W$1&" (10)",""))<lenb($Z6),10,IF(lenb(SUBSTITUTE($Z6,W$1,""))<lenb($Z6),"ERROR",IF($Z6=$Y$1,"-",0)))))))))))) -> - | X6: =IF(lenb(SUBSTITUTE($Z6,X$1&" (1)",""))<lenb($Z6),1,IF(lenb(SUBSTITUTE($Z6,X$1&" (2)",""))<lenb($Z6),2,IF(lenb(SUBSTITUTE($Z6,X$1&" (3)",""))<lenb($Z6),3,IF(lenb(SUBSTITUTE($Z6,X$1&" (4)",""))<lenb($Z6),4,IF(lenb(SUBSTITUTE($Z6,X$1&" (5)",""))<lenb($Z6),5,IF(lenb(SUBSTITUTE($Z6,X$1&" (6)",""))<lenb($Z6),6,IF(lenb(SUBSTITUTE($Z6,X$1&" (7)",""))<lenb($Z6),1,IF(lenb(SUBSTITUTE($Z6,X$1&" (8)",""))<lenb($Z6),8,IF(lenb(SUBSTITUTE($Z6,X$1&" (9)",""))<lenb($Z6),9,IF(lenb(SUBSTITUTE($Z6,X$1&" (10)",""))<lenb($Z6),10,IF(lenb(SUBSTITUTE($Z6,X$1,""))<lenb($Z6),"ERROR",IF($Z6=$Y$1,"-",0)))))))))))) -> - | Y6: =IF(Z6=Y$1,1,"-") -> 1 | Z6: No links | AA6: =ifs(U6="","",U6="-",0,U6="Erro",0,U6<>"",LEN(U6)-LEN(SUBSTITUTE(U6,CHAR(10),""))+1) -> 0 | AB6: =COUNTIFS(Links!B:B,"ICSE",Links!C:C,A6,Links!AD:AD,1) -> 0 | AC6: - | AD6: =ifs(AE6="None.","No",AE6="-","No",AND(AE6<>"None.",AE6<>"-"),"Yes") -> No | AE6: - | AF6: ---- | AG6: ---- | AH6: ---- | AI6: =IF(AH6="----",IF(AG6="----",IF(AF6="----","----",AF6),AF6&CHAR(10)&AG6),AF6&CHAR(10)&AG6&CHAR(10)&AH6) -> ---- | AJ6: =IFERROR( if(and(K6="Yes",AD6="No"),"Paper has link but no statement", if(and(K6="No",AD6="No"),"Paper has no link and no statement", if(and(K6="Yes",AD6="Yes"),"Paper has link and statement", if(and(K6="No",AD6="Yes"),"Paper has no link but has statement","")))),"") -> Paper has no link and no statement | AK6: 45035 | AL6: Technical | AM6: ="[IP"&TEXT(A6,"0000")&"]" -> [IP1848]
A7: 1849 | B7: Performance regression testing target prioritization via performance risk analysis | C7: 2014 | D7: No | E7: - | F7: - | G7: - | H7: - | I7: - | J7: - | K7: Yes | L7: Yes | M7: No | N7: No | O7: Yes | P7: No | Q7: No | R7: Yes | S7: - 4. IMPLEMENTATION - 8. CONCLUSIONS AND FUTURE WORK - FN 2 - 5. EVALUATION * | T7: http://cseweb.ucsd.edu/~peh003/perfscope http://ideone.com/6d70fJ | U7: http://cseweb.ucsd.edu/~peh003/perfscope http://ideone.com/6d70fJ | V7: =IF(lenb(SUBSTITUTE($Z7,V$1&" (1)",""))<lenb($Z7),1,IF(lenb(SUBSTITUTE($Z7,V$1&" (2)",""))<lenb($Z7),2,IF(lenb(SUBSTITUTE($Z7,V$1&" (3)",""))<lenb($Z7),3,IF(lenb(SUBSTITUTE($Z7,V$1&" (4)",""))<lenb($Z7),4,IF(lenb(SUBSTITUTE($Z7,V$1&" (5)",""))<lenb($Z7),5,IF(lenb(SUBSTITUTE($Z7,V$1&" (6)",""))<lenb($Z7),6,IF(lenb(SUBSTITUTE($Z7,V$1&" (7)",""))<lenb($Z7),1,IF(lenb(SUBSTITUTE($Z7,V$1&" (8)",""))<lenb($Z7),8,IF(lenb(SUBSTITUTE($Z7,V$1&" (9)",""))<lenb($Z7),9,IF(lenb(SUBSTITUTE($Z7,V$1&" (10)",""))<lenb($Z7),10,IF(lenb(SUBSTITUTE($Z7,V$1,""))<lenb($Z7),"ERROR",IF($Z7=$Y$1,"-",0)))))))))))) -> 2 | W7: =IF(lenb(SUBSTITUTE($Z7,W$1&" (1)",""))<lenb($Z7),1,IF(lenb(SUBSTITUTE($Z7,W$1&" (2)",""))<lenb($Z7),2,IF(lenb(SUBSTITUTE($Z7,W$1&" (3)",""))<lenb($Z7),3,IF(lenb(SUBSTITUTE($Z7,W$1&" (4)",""))<lenb($Z7),4,IF(lenb(SUBSTITUTE($Z7,W$1&" (5)",""))<lenb($Z7),5,IF(lenb(SUBSTITUTE($Z7,W$1&" (6)",""))<lenb($Z7),6,IF(lenb(SUBSTITUTE($Z7,W$1&" (7)",""))<lenb($Z7),1,IF(lenb(SUBSTITUTE($Z7,W$1&" (8)",""))<lenb($Z7),8,IF(lenb(SUBSTITUTE($Z7,W$1&" (9)",""))<lenb($Z7),9,IF(lenb(SUBSTITUTE($Z7,W$1&" (10)",""))<lenb($Z7),10,IF(lenb(SUBSTITUTE($Z7,W$1,""))<lenb($Z7),"ERROR",IF($Z7=$Y$1,"-",0)))))))))))) -> 0 | X7: =IF(lenb(SUBSTITUTE($Z7,X$1&" (1)",""))<lenb($Z7),1,IF(lenb(SUBSTITUTE($Z7,X$1&" (2)",""))<lenb($Z7),2,IF(lenb(SUBSTITUTE($Z7,X$1&" (3)",""))<lenb($Z7),3,IF(lenb(SUBSTITUTE($Z7,X$1&" (4)",""))<lenb($Z7),4,IF(lenb(SUBSTITUTE($Z7,X$1&" (5)",""))<lenb($Z7),5,IF(lenb(SUBSTITUTE($Z7,X$1&" (6)",""))<lenb($Z7),6,IF(lenb(SUBSTITUTE($Z7,X$1&" (7)",""))<lenb($Z7),1,IF(lenb(SUBSTITUTE($Z7,X$1&" (8)",""))<lenb($Z7),8,IF(lenb(SUBSTITUTE($Z7,X$1&" (9)",""))<lenb($Z7),9,IF(lenb(SUBSTITUTE($Z7,X$1&" (10)",""))<lenb($Z7),10,IF(lenb(SUBSTITUTE($Z7,X$1,""))<lenb($Z7),"ERROR",IF($Z7=$Y$1,"-",0)))))))))))) -> 0 | Y7: =IF(Z7=Y$1,1,"-") -> - | Z7: Publicly available (2) | AA7: =ifs(U7="","",U7="-",0,U7="Erro",0,U7<>"",LEN(U7)-LEN(SUBSTITUTE(U7,CHAR(10),""))+1) -> 2 | AB7: =COUNTIFS(Links!B:B,"ICSE",Links!C:C,A7,Links!AD:AD,1) -> 1 | AC7: No | AD7: =ifs(AE7="None.","No",AE7="-","No",AND(AE7<>"None.",AE7<>"-"),"Yes") -> No | AE7: - | AF7: ---- | AG7: ---- | AH7: ---- | AI7: =IF(AH7="----",IF(AG7="----",IF(AF7="----","----",AF7),AF7&CHAR(10)&AG7),AF7&CHAR(10)&AG7&CHAR(10)&AH7) -> ---- | AJ7: =IFERROR( if(and(K7="Yes",AD7="No"),"Paper has link but no statement", if(and(K7="No",AD7="No"),"Paper has no link and no statement", if(and(K7="Yes",AD7="Yes"),"Paper has link and statement", if(and(K7="No",AD7="Yes"),"Paper has no link but has statement","")))),"") -> Paper has link but no statement | AK7: 45035 | AL7: Technical | AM7: ="[IP"&TEXT(A7,"0000")&"]" -> [IP1849]
A8: 1850 | B8: Code coverage for suite evaluation by developers | C8: 2014 | D8: No | E8: - | F8: - | G8: - | H8: - | I8: - | J8: - | K8: Yes | L8: No | M8: Yes | N8: No | O8: No | P8: No | Q8: No | R8: Yes | S8: [17] 3. METHODOLOGY | T8: http://dx.doi.org/10.7910/DVN/24574 ( real link: https://dataverse.harvard.edu/dataset.xhtml?persistentId=doi:10.7910/DVN/24574 ) | U8: http://dx.doi.org/10.7910/DVN/24574 | V8: =IF(lenb(SUBSTITUTE($Z8,V$1&" (1)",""))<lenb($Z8),1,IF(lenb(SUBSTITUTE($Z8,V$1&" (2)",""))<lenb($Z8),2,IF(lenb(SUBSTITUTE($Z8,V$1&" (3)",""))<lenb($Z8),3,IF(lenb(SUBSTITUTE($Z8,V$1&" (4)",""))<lenb($Z8),4,IF(lenb(SUBSTITUTE($Z8,V$1&" (5)",""))<lenb($Z8),5,IF(lenb(SUBSTITUTE($Z8,V$1&" (6)",""))<lenb($Z8),6,IF(lenb(SUBSTITUTE($Z8,V$1&" (7)",""))<lenb($Z8),1,IF(lenb(SUBSTITUTE($Z8,V$1&" (8)",""))<lenb($Z8),8,IF(lenb(SUBSTITUTE($Z8,V$1&" (9)",""))<lenb($Z8),9,IF(lenb(SUBSTITUTE($Z8,V$1&" (10)",""))<lenb($Z8),10,IF(lenb(SUBSTITUTE($Z8,V$1,""))<lenb($Z8),"ERROR",IF($Z8=$Y$1,"-",0)))))))))))) -> 1 | W8: =IF(lenb(SUBSTITUTE($Z8,W$1&" (1)",""))<lenb($Z8),1,IF(lenb(SUBSTITUTE($Z8,W$1&" (2)",""))<lenb($Z8),2,IF(lenb(SUBSTITUTE($Z8,W$1&" (3)",""))<lenb($Z8),3,IF(lenb(SUBSTITUTE($Z8,W$1&" (4)",""))<lenb($Z8),4,IF(lenb(SUBSTITUTE($Z8,W$1&" (5)",""))<lenb($Z8),5,IF(lenb(SUBSTITUTE($Z8,W$1&" (6)",""))<lenb($Z8),6,IF(lenb(SUBSTITUTE($Z8,W$1&" (7)",""))<lenb($Z8),1,IF(lenb(SUBSTITUTE($Z8,W$1&" (8)",""))<lenb($Z8),8,IF(lenb(SUBSTITUTE($Z8,W$1&" (9)",""))<lenb($Z8),9,IF(lenb(SUBSTITUTE($Z8,W$1&" (10)",""))<lenb($Z8),10,IF(lenb(SUBSTITUTE($Z8,W$1,""))<lenb($Z8),"ERROR",IF($Z8=$Y$1,"-",0)))))))))))) -> 0 | X8: =IF(lenb(SUBSTITUTE($Z8,X$1&" (1)",""))<lenb($Z8),1,IF(lenb(SUBSTITUTE($Z8,X$1&" (2)",""))<lenb($Z8),2,IF(lenb(SUBSTITUTE($Z8,X$1&" (3)",""))<lenb($Z8),3,IF(lenb(SUBSTITUTE($Z8,X$1&" (4)",""))<lenb($Z8),4,IF(lenb(SUBSTITUTE($Z8,X$1&" (5)",""))<lenb($Z8),5,IF(lenb(SUBSTITUTE($Z8,X$1&" (6)",""))<lenb($Z8),6,IF(lenb(SUBSTITUTE($Z8,X$1&" (7)",""))<lenb($Z8),1,IF(lenb(SUBSTITUTE($Z8,X$1&" (8)",""))<lenb($Z8),8,IF(lenb(SUBSTITUTE($Z8,X$1&" (9)",""))<lenb($Z8),9,IF(lenb(SUBSTITUTE($Z8,X$1&" (10)",""))<lenb($Z8),10,IF(lenb(SUBSTITUTE($Z8,X$1,""))<lenb($Z8),"ERROR",IF($Z8=$Y$1,"-",0)))))))))))) -> 0 | Y8: =IF(Z8=Y$1,1,"-") -> - | Z8: Publicly available (1) | AA8: =ifs(U8="","",U8="-",0,U8="Erro",0,U8<>"",LEN(U8)-LEN(SUBSTITUTE(U8,CHAR(10),""))+1) -> 1 | AB8: =COUNTIFS(Links!B:B,"ICSE",Links!C:C,A8,Links!AD:AD,1) -> 1 | AC8: Yes | AD8: =ifs(AE8="None.","No",AE8="-","No",AND(AE8<>"None.",AE8<>"-"),"Yes") -> No | AE8: - | AF8: ---- | AG8: ---- | AH8: ---- | AI8: =IF(AH8="----",IF(AG8="----",IF(AF8="----","----",AF8),AF8&CHAR(10)&AG8),AF8&CHAR(10)&AG8&CHAR(10)&AH8) -> ---- | AJ8: =IFERROR( if(and(K8="Yes",AD8="No"),"Paper has link but no statement", if(and(K8="No",AD8="No"),"Paper has no link and no statement", if(and(K8="Yes",AD8="Yes"),"Paper has link and statement", if(and(K8="No",AD8="Yes"),"Paper has no link but has statement","")))),"") -> Paper has link but no statement | AK8: 45035 | AL8: Technical | AM8: ="[IP"&TEXT(A8,"0000")&"]" -> [IP1850]
A9: 1851 | B9: Time pressure: a controlled experiment of test case development and requirements review | C9: 2014 | D9: No | E9: - | F9: - | G9: - | H9: - | I9: - | J9: - | K9: Yes | L9: No | M9: Yes | N9: No | O9: No | P9: No | Q9: No | R9: Yes | S9: [39] - 3. RESEARCH METHODOLOGY * (4x) - 5. DISCUSSION * - 5.2 Threats to Validity | T9: http://users.tkk.fi/~mmantyla/TP/ | U9: http://users.tkk.fi/~mmantyla/TP/ | V9: =IF(lenb(SUBSTITUTE($Z9,V$1&" (1)",""))<lenb($Z9),1,IF(lenb(SUBSTITUTE($Z9,V$1&" (2)",""))<lenb($Z9),2,IF(lenb(SUBSTITUTE($Z9,V$1&" (3)",""))<lenb($Z9),3,IF(lenb(SUBSTITUTE($Z9,V$1&" (4)",""))<lenb($Z9),4,IF(lenb(SUBSTITUTE($Z9,V$1&" (5)",""))<lenb($Z9),5,IF(lenb(SUBSTITUTE($Z9,V$1&" (6)",""))<lenb($Z9),6,IF(lenb(SUBSTITUTE($Z9,V$1&" (7)",""))<lenb($Z9),1,IF(lenb(SUBSTITUTE($Z9,V$1&" (8)",""))<lenb($Z9),8,IF(lenb(SUBSTITUTE($Z9,V$1&" (9)",""))<lenb($Z9),9,IF(lenb(SUBSTITUTE($Z9,V$1&" (10)",""))<lenb($Z9),10,IF(lenb(SUBSTITUTE($Z9,V$1,""))<lenb($Z9),"ERROR",IF($Z9=$Y$1,"-",0)))))))))))) -> 0 | W9: =IF(lenb(SUBSTITUTE($Z9,W$1&" (1)",""))<lenb($Z9),1,IF(lenb(SUBSTITUTE($Z9,W$1&" (2)",""))<lenb($Z9),2,IF(lenb(SUBSTITUTE($Z9,W$1&" (3)",""))<lenb($Z9),3,IF(lenb(SUBSTITUTE($Z9,W$1&" (4)",""))<lenb($Z9),4,IF(lenb(SUBSTITUTE($Z9,W$1&" (5)",""))<lenb($Z9),5,IF(lenb(SUBSTITUTE($Z9,W$1&" (6)",""))<lenb($Z9),6,IF(lenb(SUBSTITUTE($Z9,W$1&" (7)",""))<lenb($Z9),1,IF(lenb(SUBSTITUTE($Z9,W$1&" (8)",""))<lenb($Z9),8,IF(lenb(SUBSTITUTE($Z9,W$1&" (9)",""))<lenb($Z9),9,IF(lenb(SUBSTITUTE($Z9,W$1&" (10)",""))<lenb($Z9),10,IF(lenb(SUBSTITUTE($Z9,W$1,""))<lenb($Z9),"ERROR",IF($Z9=$Y$1,"-",0)))))))))))) -> 1 | X9: =IF(lenb(SUBSTITUTE($Z9,X$1&" (1)",""))<lenb($Z9),1,IF(lenb(SUBSTITUTE($Z9,X$1&" (2)",""))<lenb($Z9),2,IF(lenb(SUBSTITUTE($Z9,X$1&" (3)",""))<lenb($Z9),3,IF(lenb(SUBSTITUTE($Z9,X$1&" (4)",""))<lenb($Z9),4,IF(lenb(SUBSTITUTE($Z9,X$1&" (5)",""))<lenb($Z9),5,IF(lenb(SUBSTITUTE($Z9,X$1&" (6)",""))<lenb($Z9),6,IF(lenb(SUBSTITUTE($Z9,X$1&" (7)",""))<lenb($Z9),1,IF(lenb(SUBSTITUTE($Z9,X$1&" (8)",""))<lenb($Z9),8,IF(lenb(SUBSTITUTE($Z9,X$1&" (9)",""))<lenb($Z9),9,IF(lenb(SUBSTITUTE($Z9,X$1&" (10)",""))<lenb($Z9),10,IF(lenb(SUBSTITUTE($Z9,X$1,""))<lenb($Z9),"ERROR",IF($Z9=$Y$1,"-",0)))))))))))) -> 0 | Y9: =IF(Z9=Y$1,1,"-") -> - | Z9: Not available (1) - Broken link. | AA9: =ifs(U9="","",U9="-",0,U9="Erro",0,U9<>"",LEN(U9)-LEN(SUBSTITUTE(U9,CHAR(10),""))+1) -> 1 | AB9: =COUNTIFS(Links!B:B,"ICSE",Links!C:C,A9,Links!AD:AD,1) -> 0 | AC9: No | AD9: =ifs(AE9="None.","No",AE9="-","No",AND(AE9<>"None.",AE9<>"-"),"Yes") -> No | AE9: - | AF9: ---- | AG9: ---- | AH9: ---- | AI9: =IF(AH9="----",IF(AG9="----",IF(AF9="----","----",AF9),AF9&CHAR(10)&AG9),AF9&CHAR(10)&AG9&CHAR(10)&AH9) -> ---- | AJ9: =IFERROR( if(and(K9="Yes",AD9="No"),"Paper has link but no statement", if(and(K9="No",AD9="No"),"Paper has no link and no statement", if(and(K9="Yes",AD9="Yes"),"Paper has link and statement", if(and(K9="No",AD9="Yes"),"Paper has no link but has statement","")))),"") -> Paper has link but no statement | AK9: 45035 | AL9: Technical | AM9: ="[IP"&TEXT(A9,"0000")&"]" -> [IP1851]
A10: 1852 | B10: Verifying component and connector models against crosscutting structural views | C10: 2014 | D10: No | E10: - | F10: - | G10: - | H10: - | I10: - | J10: - | K10: Yes | L10: No | M10: Yes | N10: No | O10: No | P10: No | Q10: No | R10: Yes | S10: [3] 2. OVERVIEW * 3. PRELIMINARIES 4. C&C VIEWS VERIFICATION * (2x) 5. EVALUATION (3x) * | T10: http://www.se-rwth.de/materials/cncviews/ | U10: http://www.se-rwth.de/materials/cncviews/ | V10: =IF(lenb(SUBSTITUTE($Z10,V$1&" (1)",""))<lenb($Z10),1,IF(lenb(SUBSTITUTE($Z10,V$1&" (2)",""))<lenb($Z10),2,IF(lenb(SUBSTITUTE($Z10,V$1&" (3)",""))<lenb($Z10),3,IF(lenb(SUBSTITUTE($Z10,V$1&" (4)",""))<lenb($Z10),4,IF(lenb(SUBSTITUTE($Z10,V$1&" (5)",""))<lenb($Z10),5,IF(lenb(SUBSTITUTE($Z10,V$1&" (6)",""))<lenb($Z10),6,IF(lenb(SUBSTITUTE($Z10,V$1&" (7)",""))<lenb($Z10),1,IF(lenb(SUBSTITUTE($Z10,V$1&" (8)",""))<lenb($Z10),8,IF(lenb(SUBSTITUTE($Z10,V$1&" (9)",""))<lenb($Z10),9,IF(lenb(SUBSTITUTE($Z10,V$1&" (10)",""))<lenb($Z10),10,IF(lenb(SUBSTITUTE($Z10,V$1,""))<lenb($Z10),"ERROR",IF($Z10=$Y$1,"-",0)))))))))))) -> 1 | W10: =IF(lenb(SUBSTITUTE($Z10,W$1&" (1)",""))<lenb($Z10),1,IF(lenb(SUBSTITUTE($Z10,W$1&" (2)",""))<lenb($Z10),2,IF(lenb(SUBSTITUTE($Z10,W$1&" (3)",""))<lenb($Z10),3,IF(lenb(SUBSTITUTE($Z10,W$1&" (4)",""))<lenb($Z10),4,IF(lenb(SUBSTITUTE($Z10,W$1&" (5)",""))<lenb($Z10),5,IF(lenb(SUBSTITUTE($Z10,W$1&" (6)",""))<lenb($Z10),6,IF(lenb(SUBSTITUTE($Z10,W$1&" (7)",""))<lenb($Z10),1,IF(lenb(SUBSTITUTE($Z10,W$1&" (8)",""))<lenb($Z10),8,IF(lenb(SUBSTITUTE($Z10,W$1&" (9)",""))<lenb($Z10),9,IF(lenb(SUBSTITUTE($Z10,W$1&" (10)",""))<lenb($Z10),10,IF(lenb(SUBSTITUTE($Z10,W$1,""))<lenb($Z10),"ERROR",IF($Z10=$Y$1,"-",0)))))))))))) -> 0 | X10: =IF(lenb(SUBSTITUTE($Z10,X$1&" (1)",""))<lenb($Z10),1,IF(lenb(SUBSTITUTE($Z10,X$1&" (2)",""))<lenb($Z10),2,IF(lenb(SUBSTITUTE($Z10,X$1&" (3)",""))<lenb($Z10),3,IF(lenb(SUBSTITUTE($Z10,X$1&" (4)",""))<lenb($Z10),4,IF(lenb(SUBSTITUTE($Z10,X$1&" (5)",""))<lenb($Z10),5,IF(lenb(SUBSTITUTE($Z10,X$1&" (6)",""))<lenb($Z10),6,IF(lenb(SUBSTITUTE($Z10,X$1&" (7)",""))<lenb($Z10),1,IF(lenb(SUBSTITUTE($Z10,X$1&" (8)",""))<lenb($Z10),8,IF(lenb(SUBSTITUTE($Z10,X$1&" (9)",""))<lenb($Z10),9,IF(lenb(SUBSTITUTE($Z10,X$1&" (10)",""))<lenb($Z10),10,IF(lenb(SUBSTITUTE($Z10,X$1,""))<lenb($Z10),"ERROR",IF($Z10=$Y$1,"-",0)))))))))))) -> 0 | Y10: =IF(Z10=Y$1,1,"-") -> - | Z10: Publicly available (1) | AA10: =ifs(U10="","",U10="-",0,U10="Erro",0,U10<>"",LEN(U10)-LEN(SUBSTITUTE(U10,CHAR(10),""))+1) -> 1 | AB10: =COUNTIFS(Links!B:B,"ICSE",Links!C:C,A10,Links!AD:AD,1) -> 1 | AC10: No | AD10: =ifs(AE10="None.","No",AE10="-","No",AND(AE10<>"None.",AE10<>"-"),"Yes") -> No | AE10: - | AF10: ---- | AG10: ---- | AH10: ---- | AI10: =IF(AH10="----",IF(AG10="----",IF(AF10="----","----",AF10),AF10&CHAR(10)&AG10),AF10&CHAR(10)&AG10&CHAR(10)&AH10) -> ---- | AJ10: =IFERROR( if(and(K10="Yes",AD10="No"),"Paper has link but no statement", if(and(K10="No",AD10="No"),"Paper has no link and no statement", if(and(K10="Yes",AD10="Yes"),"Paper has link and statement", if(and(K10="No",AD10="Yes"),"Paper has no link but has statement","")))),"") -> Paper has link but no statement | AK10: 45035 | AL10: Technical | AM10: ="[IP"&TEXT(A10,"0000")&"]" -> [IP1852]
A11: 1853 | B11: TradeMaker: automated dynamic analysis of synthesized tradespaces | C11: 2014 | D11: No | E11: - | F11: - | G11: - | H11: - | I11: - | J11: - | K11: Yes | L11: Yes | M11: No | N11: No | O11: No | P11: No | Q11: No | R11: Yes | S11: - FN 1 - 2. DRIVING PROBLEM - 5. DYNAMIC ANALYSIS EXPERIMENT * | T11: http://jazz.cs.virginia.edu:8080/Trademaker/data | U11: http://jazz.cs.virginia.edu:8080/Trademaker/data | V11: =IF(lenb(SUBSTITUTE($Z11,V$1&" (1)",""))<lenb($Z11),1,IF(lenb(SUBSTITUTE($Z11,V$1&" (2)",""))<lenb($Z11),2,IF(lenb(SUBSTITUTE($Z11,V$1&" (3)",""))<lenb($Z11),3,IF(lenb(SUBSTITUTE($Z11,V$1&" (4)",""))<lenb($Z11),4,IF(lenb(SUBSTITUTE($Z11,V$1&" (5)",""))<lenb($Z11),5,IF(lenb(SUBSTITUTE($Z11,V$1&" (6)",""))<lenb($Z11),6,IF(lenb(SUBSTITUTE($Z11,V$1&" (7)",""))<lenb($Z11),1,IF(lenb(SUBSTITUTE($Z11,V$1&" (8)",""))<lenb($Z11),8,IF(lenb(SUBSTITUTE($Z11,V$1&" (9)",""))<lenb($Z11),9,IF(lenb(SUBSTITUTE($Z11,V$1&" (10)",""))<lenb($Z11),10,IF(lenb(SUBSTITUTE($Z11,V$1,""))<lenb($Z11),"ERROR",IF($Z11=$Y$1,"-",0)))))))))))) -> 0 | W11: =IF(lenb(SUBSTITUTE($Z11,W$1&" (1)",""))<lenb($Z11),1,IF(lenb(SUBSTITUTE($Z11,W$1&" (2)",""))<lenb($Z11),2,IF(lenb(SUBSTITUTE($Z11,W$1&" (3)",""))<lenb($Z11),3,IF(lenb(SUBSTITUTE($Z11,W$1&" (4)",""))<lenb($Z11),4,IF(lenb(SUBSTITUTE($Z11,W$1&" (5)",""))<lenb($Z11),5,IF(lenb(SUBSTITUTE($Z11,W$1&" (6)",""))<lenb($Z11),6,IF(lenb(SUBSTITUTE($Z11,W$1&" (7)",""))<lenb($Z11),1,IF(lenb(SUBSTITUTE($Z11,W$1&" (8)",""))<lenb($Z11),8,IF(lenb(SUBSTITUTE($Z11,W$1&" (9)",""))<lenb($Z11),9,IF(lenb(SUBSTITUTE($Z11,W$1&" (10)",""))<lenb($Z11),10,IF(lenb(SUBSTITUTE($Z11,W$1,""))<lenb($Z11),"ERROR",IF($Z11=$Y$1,"-",0)))))))))))) -> 1 | X11: =IF(lenb(SUBSTITUTE($Z11,X$1&" (1)",""))<lenb($Z11),1,IF(lenb(SUBSTITUTE($Z11,X$1&" (2)",""))<lenb($Z11),2,IF(lenb(SUBSTITUTE($Z11,X$1&" (3)",""))<lenb($Z11),3,IF(lenb(SUBSTITUTE($Z11,X$1&" (4)",""))<lenb($Z11),4,IF(lenb(SUBSTITUTE($Z11,X$1&" (5)",""))<lenb($Z11),5,IF(lenb(SUBSTITUTE($Z11,X$1&" (6)",""))<lenb($Z11),6,IF(lenb(SUBSTITUTE($Z11,X$1&" (7)",""))<lenb($Z11),1,IF(lenb(SUBSTITUTE($Z11,X$1&" (8)",""))<lenb($Z11),8,IF(lenb(SUBSTITUTE($Z11,X$1&" (9)",""))<lenb($Z11),9,IF(lenb(SUBSTITUTE($Z11,X$1&" (10)",""))<lenb($Z11),10,IF(lenb(SUBSTITUTE($Z11,X$1,""))<lenb($Z11),"ERROR",IF($Z11=$Y$1,"-",0)))))))))))) -> 0 | Y11: =IF(Z11=Y$1,1,"-") -> - | Z11: Not available (1) - Broken link. | AA11: =ifs(U11="","",U11="-",0,U11="Erro",0,U11<>"",LEN(U11)-LEN(SUBSTITUTE(U11,CHAR(10),""))+1) -> 1 | AB11: =COUNTIFS(Links!B:B,"ICSE",Links!C:C,A11,Links!AD:AD,1) -> 1 | AC11: No | AD11: =ifs(AE11="None.","No",AE11="-","No",AND(AE11<>"None.",AE11<>"-"),"Yes") -> No | AE11: - | AF11: ---- | AG11: ---- | AH11: ---- | AI11: =IF(AH11="----",IF(AG11="----",IF(AF11="----","----",AF11),AF11&CHAR(10)&AG11),AF11&CHAR(10)&AG11&CHAR(10)&AH11) -> ---- | AJ11: =IFERROR( if(and(K11="Yes",AD11="No"),"Paper has link but no statement", if(and(K11="No",AD11="No"),"Paper has no link and no statement", if(and(K11="Yes",AD11="Yes"),"Paper has link and statement", if(and(K11="No",AD11="Yes"),"Paper has no link but has statement","")))),"") -> Paper has link but no statement | AK11: 45035 | AL11: Technical | AM11: ="[IP"&TEXT(A11,"0000")&"]" -> [IP1853]
A12: 1854 | B12: Lifting model transformations to product lines | C12: 2014 | D12: No | E12: - | F12: - | G12: - | H12: - | I12: - | J12: - | K12: No | L12: - | M12: - | N12: - | O12: - | P12: - | Q12: - | R12: - | S12: - | T12: - | U12: - | V12: =IF(lenb(SUBSTITUTE($Z12,V$1&" (1)",""))<lenb($Z12),1,IF(lenb(SUBSTITUTE($Z12,V$1&" (2)",""))<lenb($Z12),2,IF(lenb(SUBSTITUTE($Z12,V$1&" (3)",""))<lenb($Z12),3,IF(lenb(SUBSTITUTE($Z12,V$1&" (4)",""))<lenb($Z12),4,IF(lenb(SUBSTITUTE($Z12,V$1&" (5)",""))<lenb($Z12),5,IF(lenb(SUBSTITUTE($Z12,V$1&" (6)",""))<lenb($Z12),6,IF(lenb(SUBSTITUTE($Z12,V$1&" (7)",""))<lenb($Z12),1,IF(lenb(SUBSTITUTE($Z12,V$1&" (8)",""))<lenb($Z12),8,IF(lenb(SUBSTITUTE($Z12,V$1&" (9)",""))<lenb($Z12),9,IF(lenb(SUBSTITUTE($Z12,V$1&" (10)",""))<lenb($Z12),10,IF(lenb(SUBSTITUTE($Z12,V$1,""))<lenb($Z12),"ERROR",IF($Z12=$Y$1,"-",0)))))))))))) -> - | W12: =IF(lenb(SUBSTITUTE($Z12,W$1&" (1)",""))<lenb($Z12),1,IF(lenb(SUBSTITUTE($Z12,W$1&" (2)",""))<lenb($Z12),2,IF(lenb(SUBSTITUTE($Z12,W$1&" (3)",""))<lenb($Z12),3,IF(lenb(SUBSTITUTE($Z12,W$1&" (4)",""))<lenb($Z12),4,IF(lenb(SUBSTITUTE($Z12,W$1&" (5)",""))<lenb($Z12),5,IF(lenb(SUBSTITUTE($Z12,W$1&" (6)",""))<lenb($Z12),6,IF(lenb(SUBSTITUTE($Z12,W$1&" (7)",""))<lenb($Z12),1,IF(lenb(SUBSTITUTE($Z12,W$1&" (8)",""))<lenb($Z12),8,IF(lenb(SUBSTITUTE($Z12,W$1&" (9)",""))<lenb($Z12),9,IF(lenb(SUBSTITUTE($Z12,W$1&" (10)",""))<lenb($Z12),10,IF(lenb(SUBSTITUTE($Z12,W$1,""))<lenb($Z12),"ERROR",IF($Z12=$Y$1,"-",0)))))))))))) -> - | X12: =IF(lenb(SUBSTITUTE($Z12,X$1&" (1)",""))<lenb($Z12),1,IF(lenb(SUBSTITUTE($Z12,X$1&" (2)",""))<lenb($Z12),2,IF(lenb(SUBSTITUTE($Z12,X$1&" (3)",""))<lenb($Z12),3,IF(lenb(SUBSTITUTE($Z12,X$1&" (4)",""))<lenb($Z12),4,IF(lenb(SUBSTITUTE($Z12,X$1&" (5)",""))<lenb($Z12),5,IF(lenb(SUBSTITUTE($Z12,X$1&" (6)",""))<lenb($Z12),6,IF(lenb(SUBSTITUTE($Z12,X$1&" (7)",""))<lenb($Z12),1,IF(lenb(SUBSTITUTE($Z12,X$1&" (8)",""))<lenb($Z12),8,IF(lenb(SUBSTITUTE($Z12,X$1&" (9)",""))<lenb($Z12),9,IF(lenb(SUBSTITUTE($Z12,X$1&" (10)",""))<lenb($Z12),10,IF(lenb(SUBSTITUTE($Z12,X$1,""))<lenb($Z12),"ERROR",IF($Z12=$Y$1,"-",0)))))))))))) -> - | Y12: =IF(Z12=Y$1,1,"-") -> 1 | Z12: No links | AA12: =ifs(U12="","",U12="-",0,U12="Erro",0,U12<>"",LEN(U12)-LEN(SUBSTITUTE(U12,CHAR(10),""))+1) -> 0 | AB12: =COUNTIFS(Links!B:B,"ICSE",Links!C:C,A12,Links!AD:AD,1) -> 0 | AC12: - | AD12: =ifs(AE12="None.","No",AE12="-","No",AND(AE12<>"None.",AE12<>"-"),"Yes") -> No | AE12: - | AF12: ---- | AG12: ---- | AH12: ---- | AI12: =IF(AH12="----",IF(AG12="----",IF(AF12="----","----",AF12),AF12&CHAR(10)&AG12),AF12&CHAR(10)&AG12&CHAR(10)&AH12) -> ---- | AJ12: =IFERROR( if(and(K12="Yes",AD12="No"),"Paper has link but no statement", if(and(K12="No",AD12="No"),"Paper has no link and no statement", if(and(K12="Yes",AD12="Yes"),"Paper has link and statement", if(and(K12="No",AD12="Yes"),"Paper has no link but has statement","")))),"") -> Paper has no link and no statement | AK12: 45035 | AL12: Technical | AM12: ="[IP"&TEXT(A12,"0000")&"]" -> [IP1854]
A13: 1855 | B13: Automated goal operationalisation based on interpolation and SAT solving | C13: 2014 | D13: No | E13: - | F13: - | G13: - | H13: - | I13: - | J13: - | K13: Yes | L13: No | M13: No | N13: No | O13: No | P13: No | Q13: No | R13: Yes | S13: 6. DEMONSTRATING EXAMPLES | T13: http://dc.exa.unrc.edu.ar/staff/rdegiovanni/icse2014.zip | U13: http://dc.exa.unrc.edu.ar/staff/rdegiovanni/icse2014.zip | V13: =IF(lenb(SUBSTITUTE($Z13,V$1&" (1)",""))<lenb($Z13),1,IF(lenb(SUBSTITUTE($Z13,V$1&" (2)",""))<lenb($Z13),2,IF(lenb(SUBSTITUTE($Z13,V$1&" (3)",""))<lenb($Z13),3,IF(lenb(SUBSTITUTE($Z13,V$1&" (4)",""))<lenb($Z13),4,IF(lenb(SUBSTITUTE($Z13,V$1&" (5)",""))<lenb($Z13),5,IF(lenb(SUBSTITUTE($Z13,V$1&" (6)",""))<lenb($Z13),6,IF(lenb(SUBSTITUTE($Z13,V$1&" (7)",""))<lenb($Z13),1,IF(lenb(SUBSTITUTE($Z13,V$1&" (8)",""))<lenb($Z13),8,IF(lenb(SUBSTITUTE($Z13,V$1&" (9)",""))<lenb($Z13),9,IF(lenb(SUBSTITUTE($Z13,V$1&" (10)",""))<lenb($Z13),10,IF(lenb(SUBSTITUTE($Z13,V$1,""))<lenb($Z13),"ERROR",IF($Z13=$Y$1,"-",0)))))))))))) -> 1 | W13: =IF(lenb(SUBSTITUTE($Z13,W$1&" (1)",""))<lenb($Z13),1,IF(lenb(SUBSTITUTE($Z13,W$1&" (2)",""))<lenb($Z13),2,IF(lenb(SUBSTITUTE($Z13,W$1&" (3)",""))<lenb($Z13),3,IF(lenb(SUBSTITUTE($Z13,W$1&" (4)",""))<lenb($Z13),4,IF(lenb(SUBSTITUTE($Z13,W$1&" (5)",""))<lenb($Z13),5,IF(lenb(SUBSTITUTE($Z13,W$1&" (6)",""))<lenb($Z13),6,IF(lenb(SUBSTITUTE($Z13,W$1&" (7)",""))<lenb($Z13),1,IF(lenb(SUBSTITUTE($Z13,W$1&" (8)",""))<lenb($Z13),8,IF(lenb(SUBSTITUTE($Z13,W$1&" (9)",""))<lenb($Z13),9,IF(lenb(SUBSTITUTE($Z13,W$1&" (10)",""))<lenb($Z13),10,IF(lenb(SUBSTITUTE($Z13,W$1,""))<lenb($Z13),"ERROR",IF($Z13=$Y$1,"-",0)))))))))))) -> 0 | X13: =IF(lenb(SUBSTITUTE($Z13,X$1&" (1)",""))<lenb($Z13),1,IF(lenb(SUBSTITUTE($Z13,X$1&" (2)",""))<lenb($Z13),2,IF(lenb(SUBSTITUTE($Z13,X$1&" (3)",""))<lenb($Z13),3,IF(lenb(SUBSTITUTE($Z13,X$1&" (4)",""))<lenb($Z13),4,IF(lenb(SUBSTITUTE($Z13,X$1&" (5)",""))<lenb($Z13),5,IF(lenb(SUBSTITUTE($Z13,X$1&" (6)",""))<lenb($Z13),6,IF(lenb(SUBSTITUTE($Z13,X$1&" (7)",""))<lenb($Z13),1,IF(lenb(SUBSTITUTE($Z13,X$1&" (8)",""))<lenb($Z13),8,IF(lenb(SUBSTITUTE($Z13,X$1&" (9)",""))<lenb($Z13),9,IF(lenb(SUBSTITUTE($Z13,X$1&" (10)",""))<lenb($Z13),10,IF(lenb(SUBSTITUTE($Z13,X$1,""))<lenb($Z13),"ERROR",IF($Z13=$Y$1,"-",0)))))))))))) -> 0 | Y13: =IF(Z13=Y$1,1,"-") -> - | Z13: Publicly available (1) | AA13: =ifs(U13="","",U13="-",0,U13="Erro",0,U13<>"",LEN(U13)-LEN(SUBSTITUTE(U13,CHAR(10),""))+1) -> 1 | AB13: =COUNTIFS(Links!B:B,"ICSE",Links!C:C,A13,Links!AD:AD,1) -> 1 | AC13: No | AD13: =ifs(AE13="None.","No",AE13="-","No",AND(AE13<>"None.",AE13<>"-"),"Yes") -> No | AE13: - | AF13: ---- | AG13: ---- | AH13: ---- | AI13: =IF(AH13="----",IF(AG13="----",IF(AF13="----","----",AF13),AF13&CHAR(10)&AG13),AF13&CHAR(10)&AG13&CHAR(10)&AH13) -> ---- | AJ13: =IFERROR( if(and(K13="Yes",AD13="No"),"Paper has link but no statement", if(and(K13="No",AD13="No"),"Paper has no link and no statement", if(and(K13="Yes",AD13="Yes"),"Paper has link and statement", if(and(K13="No",AD13="Yes"),"Paper has no link but has statement","")))),"") -> Paper has link but no statement | AK13: 45035 | AL13: Technical | AM13: ="[IP"&TEXT(A13,"0000")&"]" -> [IP1855]
... A652: 780 | B652: On the Recall of Static Call Graph Construction in Practice | C652: 2020 | D652: Yes | E652: Yes | F652: No | G652: Yes | H652: No | I652: No | J652: - | K652: No | L652: - | M652: - | N652: - | O652: - | P652: - | Q652: - | R652: - | S652: - | T652: - | U652: - | V652: =IF(lenb(SUBSTITUTE($Z652,V$1&" (1)",""))<lenb($Z652),1,IF(lenb(SUBSTITUTE($Z652,V$1&" (2)",""))<lenb($Z652),2,IF(lenb(SUBSTITUTE($Z652,V$1&" (3)",""))<lenb($Z652),3,IF(lenb(SUBSTITUTE($Z652,V$1&" (4)",""))<lenb($Z652),4,IF(lenb(SUBSTITUTE($Z652,V$1&" (5)",""))<lenb($Z652),5,IF(lenb(SUBSTITUTE($Z652,V$1&" (6)",""))<lenb($Z652),6,IF(lenb(SUBSTITUTE($Z652,V$1&" (7)",""))<lenb($Z652),1,IF(lenb(SUBSTITUTE($Z652,V$1&" (8)",""))<lenb($Z652),8,IF(lenb(SUBSTITUTE($Z652,V$1&" (9)",""))<lenb($Z652),9,IF(lenb(SUBSTITUTE($Z652,V$1&" (10)",""))<lenb($Z652),10,IF(lenb(SUBSTITUTE($Z652,V$1,""))<lenb($Z652),"ERROR",IF($Z652=$Y$1,"-",0)))))))))))) -> - | W652: =IF(lenb(SUBSTITUTE($Z652,W$1&" (1)",""))<lenb($Z652),1,IF(lenb(SUBSTITUTE($Z652,W$1&" (2)",""))<lenb($Z652),2,IF(lenb(SUBSTITUTE($Z652,W$1&" (3)",""))<lenb($Z652),3,IF(lenb(SUBSTITUTE($Z652,W$1&" (4)",""))<lenb($Z652),4,IF(lenb(SUBSTITUTE($Z652,W$1&" (5)",""))<lenb($Z652),5,IF(lenb(SUBSTITUTE($Z652,W$1&" (6)",""))<lenb($Z652),6,IF(lenb(SUBSTITUTE($Z652,W$1&" (7)",""))<lenb($Z652),1,IF(lenb(SUBSTITUTE($Z652,W$1&" (8)",""))<lenb($Z652),8,IF(lenb(SUBSTITUTE($Z652,W$1&" (9)",""))<lenb($Z652),9,IF(lenb(SUBSTITUTE($Z652,W$1&" (10)",""))<lenb($Z652),10,IF(lenb(SUBSTITUTE($Z652,W$1,""))<lenb($Z652),"ERROR",IF($Z652=$Y$1,"-",0)))))))))))) -> - | X652: =IF(lenb(SUBSTITUTE($Z652,X$1&" (1)",""))<lenb($Z652),1,IF(lenb(SUBSTITUTE($Z652,X$1&" (2)",""))<lenb($Z652),2,IF(lenb(SUBSTITUTE($Z652,X$1&" (3)",""))<lenb($Z652),3,IF(lenb(SUBSTITUTE($Z652,X$1&" (4)",""))<lenb($Z652),4,IF(lenb(SUBSTITUTE($Z652,X$1&" (5)",""))<lenb($Z652),5,IF(lenb(SUBSTITUTE($Z652,X$1&" (6)",""))<lenb($Z652),6,IF(lenb(SUBSTITUTE($Z652,X$1&" (7)",""))<lenb($Z652),1,IF(lenb(SUBSTITUTE($Z652,X$1&" (8)",""))<lenb($Z652),8,IF(lenb(SUBSTITUTE($Z652,X$1&" (9)",""))<lenb($Z652),9,IF(lenb(SUBSTITUTE($Z652,X$1&" (10)",""))<lenb($Z652),10,IF(lenb(SUBSTITUTE($Z652,X$1,""))<lenb($Z652),"ERROR",IF($Z652=$Y$1,"-",0)))))))))))) -> - | Y652: =IF(Z652=Y$1,1,"-") -> 1 | Z652: No links | AA652: =ifs(U652="","",U652="-",0,U652="Erro",0,U652<>"",LEN(U652)-LEN(SUBSTITUTE(U652,CHAR(10),""))+1) -> 0 | AB652: =COUNTIFS(Links!B:B,"ICSE",Links!C:C,A652,Links!AD:AD,1) -> 0 | AC652: - | AD652: =ifs(AE652="None.","No",AE652="-","No",AND(AE652<>"None.",AE652<>"-"),"Yes") -> No | AE652: - | AF652: ---- | AG652: ---- | AH652: ---- | AI652: =IF(AH652="----",IF(AG652="----",IF(AF652="----","----",AF652),AF652&CHAR(10)&AG652),AF652&CHAR(10)&AG652&CHAR(10)&AH652) -> ---- | AJ652: =IFERROR( if(and(K652="Yes",AD652="No"),"Paper has link but no statement", if(and(K652="No",AD652="No"),"Paper has no link and no statement", if(and(K652="Yes",AD652="Yes"),"Paper has link and statement", if(and(K652="No",AD652="Yes"),"Paper has no link but has statement","")))),"") -> Paper has no link and no statement | AK652: 45027 | AL652: Technical | AM652: ="[IP"&TEXT(A652,"0000")&"]" -> [IP0780]
A653: 781 | B653: Heaps'n Leaks: How Heap Snapshots Improve Android Taint Analysis | C653: 2020 | D653: Yes | E653: Yes | F653: No | G653: Yes | H653: No | I653: No | J653: - | K653: Yes | L653: No | M653: No | N653: No | O653: Yes | P653: Yes | Q653: No | R653: No | S653: 7 CONCLUSION --- HL Replicability | T653: https://bit.ly/38F5tUH (real link: https://zenodo.org/record/3627973#.Xi6jnxNKhTY) | U653: https://bit.ly/38F5tUH | V653: =IF(lenb(SUBSTITUTE($Z653,V$1&" (1)",""))<lenb($Z653),1,IF(lenb(SUBSTITUTE($Z653,V$1&" (2)",""))<lenb($Z653),2,IF(lenb(SUBSTITUTE($Z653,V$1&" (3)",""))<lenb($Z653),3,IF(lenb(SUBSTITUTE($Z653,V$1&" (4)",""))<lenb($Z653),4,IF(lenb(SUBSTITUTE($Z653,V$1&" (5)",""))<lenb($Z653),5,IF(lenb(SUBSTITUTE($Z653,V$1&" (6)",""))<lenb($Z653),6,IF(lenb(SUBSTITUTE($Z653,V$1&" (7)",""))<lenb($Z653),1,IF(lenb(SUBSTITUTE($Z653,V$1&" (8)",""))<lenb($Z653),8,IF(lenb(SUBSTITUTE($Z653,V$1&" (9)",""))<lenb($Z653),9,IF(lenb(SUBSTITUTE($Z653,V$1&" (10)",""))<lenb($Z653),10,IF(lenb(SUBSTITUTE($Z653,V$1,""))<lenb($Z653),"ERROR",IF($Z653=$Y$1,"-",0)))))))))))) -> 1 | W653: =IF(lenb(SUBSTITUTE($Z653,W$1&" (1)",""))<lenb($Z653),1,IF(lenb(SUBSTITUTE($Z653,W$1&" (2)",""))<lenb($Z653),2,IF(lenb(SUBSTITUTE($Z653,W$1&" (3)",""))<lenb($Z653),3,IF(lenb(SUBSTITUTE($Z653,W$1&" (4)",""))<lenb($Z653),4,IF(lenb(SUBSTITUTE($Z653,W$1&" (5)",""))<lenb($Z653),5,IF(lenb(SUBSTITUTE($Z653,W$1&" (6)",""))<lenb($Z653),6,IF(lenb(SUBSTITUTE($Z653,W$1&" (7)",""))<lenb($Z653),1,IF(lenb(SUBSTITUTE($Z653,W$1&" (8)",""))<lenb($Z653),8,IF(lenb(SUBSTITUTE($Z653,W$1&" (9)",""))<lenb($Z653),9,IF(lenb(SUBSTITUTE($Z653,W$1&" (10)",""))<lenb($Z653),10,IF(lenb(SUBSTITUTE($Z653,W$1,""))<lenb($Z653),"ERROR",IF($Z653=$Y$1,"-",0)))))))))))) -> 0 | X653: =IF(lenb(SUBSTITUTE($Z653,X$1&" (1)",""))<lenb($Z653),1,IF(lenb(SUBSTITUTE($Z653,X$1&" (2)",""))<lenb($Z653),2,IF(lenb(SUBSTITUTE($Z653,X$1&" (3)",""))<lenb($Z653),3,IF(lenb(SUBSTITUTE($Z653,X$1&" (4)",""))<lenb($Z653),4,IF(lenb(SUBSTITUTE($Z653,X$1&" (5)",""))<lenb($Z653),5,IF(lenb(SUBSTITUTE($Z653,X$1&" (6)",""))<lenb($Z653),6,IF(lenb(SUBSTITUTE($Z653,X$1&" (7)",""))<lenb($Z653),1,IF(lenb(SUBSTITUTE($Z653,X$1&" (8)",""))<lenb($Z653),8,IF(lenb(SUBSTITUTE($Z653,X$1&" (9)",""))<lenb($Z653),9,IF(lenb(SUBSTITUTE($Z653,X$1&" (10)",""))<lenb($Z653),10,IF(lenb(SUBSTITUTE($Z653,X$1,""))<lenb($Z653),"ERROR",IF($Z653=$Y$1,"-",0)))))))))))) -> 0 | Y653: =IF(Z653=Y$1,1,"-") -> - | Z653: Publicly available (1) | AA653: =ifs(U653="","",U653="-",0,U653="Erro",0,U653<>"",LEN(U653)-LEN(SUBSTITUTE(U653,CHAR(10),""))+1) -> 1 | AB653: =COUNTIFS(Links!B:B,"ICSE",Links!C:C,A653,Links!AD:AD,1) -> 0 | AC653: No | AD653: =ifs(AE653="None.","No",AE653="-","No",AND(AE653<>"None.",AE653<>"-"),"Yes") -> Yes | AE653: Because DroidMacroBench comprises closed-source apps we cannot legally make it available as open source. We will make it available to other researchers, though, through a password-protected website. DroidMacroBench will also be made available to the artifact evaluation. | AF653: Barriers (Agreements and legal rights) | AG653: Limited access (Credentials required) | AH653: Future plans (—) | AI653: =if(AH653="-",if(AG653="-",if(AF653="-","-",AF653),AF653&char(10)&AG653),AF653&char(10)&AG653&char(10)&AH653) -> Barriers (Agreements and legal rights) Limited access (Credentials required) Future plans (—) | AJ653: =IFERROR( if(and(K653="Yes",AD653="No"),"Paper has link but no statement", if(and(K653="No",AD653="No"),"Paper has no link and no statement", if(and(K653="Yes",AD653="Yes"),"Paper has link and statement", if(and(K653="No",AD653="Yes"),"Paper has no link but has statement","")))),"") -> Paper has link and statement | AK653: 45027 | AL653: Technical | AM653: ="[IP"&TEXT(A653,"0000")&"]" -> [IP0781]
A654: 782 | B654: Big Code != Big Vocabulary: Open-Vocabulary Models for Source Code | C654: 2020 | D654: Yes | E654: Yes | F654: No | G654: Yes | H654: No | I654: No | J654: - | K654: Yes | L654: No | M654: No | N654: No | O654: No | P654: No | Q654: Yes | R654: No | S654: - 10 ARTIFACTS --- Table 4 - 10 ARTIFACTS | T654: https://doi.org/10.5281/zenodo.3628775 https://doi.org/10.5281/zenodo.3628784 https://doi.org/10.5281/zenodo.3628665 https://doi.org/10.5281/zenodo.3628638 https://doi.org/10.5281/zenodo.3628636 https://doi.org/10.5281/zenodo.3629271 https://doi.org/10.5281/zenodo.3628628 https://github.com/mast-group/OpenVocabCodeNLM | U654: https://doi.org/10.5281/zenodo.3628775 https://doi.org/10.5281/zenodo.3628784 https://doi.org/10.5281/zenodo.3628665 https://doi.org/10.5281/zenodo.3628638 https://doi.org/10.5281/zenodo.3628636 https://doi.org/10.5281/zenodo.3629271 https://doi.org/10.5281/zenodo.3628628 https://github.com/mast-group/OpenVocabCodeNLM | V654: =IF(lenb(SUBSTITUTE($Z654,V$1&" (1)",""))<lenb($Z654),1,IF(lenb(SUBSTITUTE($Z654,V$1&" (2)",""))<lenb($Z654),2,IF(lenb(SUBSTITUTE($Z654,V$1&" (3)",""))<lenb($Z654),3,IF(lenb(SUBSTITUTE($Z654,V$1&" (4)",""))<lenb($Z654),4,IF(lenb(SUBSTITUTE($Z654,V$1&" (5)",""))<lenb($Z654),5,IF(lenb(SUBSTITUTE($Z654,V$1&" (6)",""))<lenb($Z654),6,IF(lenb(SUBSTITUTE($Z654,V$1&" (7)",""))<lenb($Z654),1,IF(lenb(SUBSTITUTE($Z654,V$1&" (8)",""))<lenb($Z654),8,IF(lenb(SUBSTITUTE($Z654,V$1&" (9)",""))<lenb($Z654),9,IF(lenb(SUBSTITUTE($Z654,V$1&" (10)",""))<lenb($Z654),10,IF(lenb(SUBSTITUTE($Z654,V$1,""))<lenb($Z654),"ERROR",IF($Z654=$Y$1,"-",0)))))))))))) -> 8 | W654: =IF(lenb(SUBSTITUTE($Z654,W$1&" (1)",""))<lenb($Z654),1,IF(lenb(SUBSTITUTE($Z654,W$1&" (2)",""))<lenb($Z654),2,IF(lenb(SUBSTITUTE($Z654,W$1&" (3)",""))<lenb($Z654),3,IF(lenb(SUBSTITUTE($Z654,W$1&" (4)",""))<lenb($Z654),4,IF(lenb(SUBSTITUTE($Z654,W$1&" (5)",""))<lenb($Z654),5,IF(lenb(SUBSTITUTE($Z654,W$1&" (6)",""))<lenb($Z654),6,IF(lenb(SUBSTITUTE($Z654,W$1&" (7)",""))<lenb($Z654),1,IF(lenb(SUBSTITUTE($Z654,W$1&" (8)",""))<lenb($Z654),8,IF(lenb(SUBSTITUTE($Z654,W$1&" (9)",""))<lenb($Z654),9,IF(lenb(SUBSTITUTE($Z654,W$1&" (10)",""))<lenb($Z654),10,IF(lenb(SUBSTITUTE($Z654,W$1,""))<lenb($Z654),"ERROR",IF($Z654=$Y$1,"-",0)))))))))))) -> 0 | X654: =IF(lenb(SUBSTITUTE($Z654,X$1&" (1)",""))<lenb($Z654),1,IF(lenb(SUBSTITUTE($Z654,X$1&" (2)",""))<lenb($Z654),2,IF(lenb(SUBSTITUTE($Z654,X$1&" (3)",""))<lenb($Z654),3,IF(lenb(SUBSTITUTE($Z654,X$1&" (4)",""))<lenb($Z654),4,IF(lenb(SUBSTITUTE($Z654,X$1&" (5)",""))<lenb($Z654),5,IF(lenb(SUBSTITUTE($Z654,X$1&" (6)",""))<lenb($Z654),6,IF(lenb(SUBSTITUTE($Z654,X$1&" (7)",""))<lenb($Z654),1,IF(lenb(SUBSTITUTE($Z654,X$1&" (8)",""))<lenb($Z654),8,IF(lenb(SUBSTITUTE($Z654,X$1&" (9)",""))<lenb($Z654),9,IF(lenb(SUBSTITUTE($Z654,X$1&" (10)",""))<lenb($Z654),10,IF(lenb(SUBSTITUTE($Z654,X$1,""))<lenb($Z654),"ERROR",IF($Z654=$Y$1,"-",0)))))))))))) -> 0 | Y654: =IF(Z654=Y$1,1,"-") -> - | Z654: Publicly available (8) | AA654: =ifs(U654="","",U654="-",0,U654="Erro",0,U654<>"",LEN(U654)-LEN(SUBSTITUTE(U654,CHAR(10),""))+1) -> 8 | AB654: =COUNTIFS(Links!B:B,"ICSE",Links!C:C,A654,Links!AD:AD,1) -> 0 | AC654: Yes | AD654: =ifs(AE654="None.","No",AE654="-","No",AND(AE654<>"None.",AE654<>"-"),"Yes") -> No | AE654: - | AF654: ---- | AG654: ---- | AH654: ---- | AI654: =IF(AH654="----",IF(AG654="----",IF(AF654="----","----",AF654),AF654&CHAR(10)&AG654),AF654&CHAR(10)&AG654&CHAR(10)&AH654) -> ---- | AJ654: =IFERROR( if(and(K654="Yes",AD654="No"),"Paper has link but no statement", if(and(K654="No",AD654="No"),"Paper has no link and no statement", if(and(K654="Yes",AD654="Yes"),"Paper has link and statement", if(and(K654="No",AD654="Yes"),"Paper has no link but has statement","")))),"") -> Paper has link but no statement | AK654: 45027 | AL654: Technical | AM654: ="[IP"&TEXT(A654,"0000")&"]" -> [IP0782]
A655: 783 | B655: Improving Data Scientist Efficiency with Provenance | C655: 2020 | D655: Yes | E655: Yes | F655: No | G655: Yes | H655: No | I655: No | J655: - | K655: Yes | L655: No | M655: Yes | N655: No | O655: No | P655: Yes | Q655: No | R655: Yes | S655: [28] 8 DISCUSSION --- HL Data Availability | T655: https://doi.org/10.5281/zenodo.3628097 | U655: https://doi.org/10.5281/zenodo.3628097 | V655: =IF(lenb(SUBSTITUTE($Z655,V$1&" (1)",""))<lenb($Z655),1,IF(lenb(SUBSTITUTE($Z655,V$1&" (2)",""))<lenb($Z655),2,IF(lenb(SUBSTITUTE($Z655,V$1&" (3)",""))<lenb($Z655),3,IF(lenb(SUBSTITUTE($Z655,V$1&" (4)",""))<lenb($Z655),4,IF(lenb(SUBSTITUTE($Z655,V$1&" (5)",""))<lenb($Z655),5,IF(lenb(SUBSTITUTE($Z655,V$1&" (6)",""))<lenb($Z655),6,IF(lenb(SUBSTITUTE($Z655,V$1&" (7)",""))<lenb($Z655),1,IF(lenb(SUBSTITUTE($Z655,V$1&" (8)",""))<lenb($Z655),8,IF(lenb(SUBSTITUTE($Z655,V$1&" (9)",""))<lenb($Z655),9,IF(lenb(SUBSTITUTE($Z655,V$1&" (10)",""))<lenb($Z655),10,IF(lenb(SUBSTITUTE($Z655,V$1,""))<lenb($Z655),"ERROR",IF($Z655=$Y$1,"-",0)))))))))))) -> 1 | W655: =IF(lenb(SUBSTITUTE($Z655,W$1&" (1)",""))<lenb($Z655),1,IF(lenb(SUBSTITUTE($Z655,W$1&" (2)",""))<lenb($Z655),2,IF(lenb(SUBSTITUTE($Z655,W$1&" (3)",""))<lenb($Z655),3,IF(lenb(SUBSTITUTE($Z655,W$1&" (4)",""))<lenb($Z655),4,IF(lenb(SUBSTITUTE($Z655,W$1&" (5)",""))<lenb($Z655),5,IF(lenb(SUBSTITUTE($Z655,W$1&" (6)",""))<lenb($Z655),6,IF(lenb(SUBSTITUTE($Z655,W$1&" (7)",""))<lenb($Z655),1,IF(lenb(SUBSTITUTE($Z655,W$1&" (8)",""))<lenb($Z655),8,IF(lenb(SUBSTITUTE($Z655,W$1&" (9)",""))<lenb($Z655),9,IF(lenb(SUBSTITUTE($Z655,W$1&" (10)",""))<lenb($Z655),10,IF(lenb(SUBSTITUTE($Z655,W$1,""))<lenb($Z655),"ERROR",IF($Z655=$Y$1,"-",0)))))))))))) -> 0 | X655: =IF(lenb(SUBSTITUTE($Z655,X$1&" (1)",""))<lenb($Z655),1,IF(lenb(SUBSTITUTE($Z655,X$1&" (2)",""))<lenb($Z655),2,IF(lenb(SUBSTITUTE($Z655,X$1&" (3)",""))<lenb($Z655),3,IF(lenb(SUBSTITUTE($Z655,X$1&" (4)",""))<lenb($Z655),4,IF(lenb(SUBSTITUTE($Z655,X$1&" (5)",""))<lenb($Z655),5,IF(lenb(SUBSTITUTE($Z655,X$1&" (6)",""))<lenb($Z655),6,IF(lenb(SUBSTITUTE($Z655,X$1&" (7)",""))<lenb($Z655),1,IF(lenb(SUBSTITUTE($Z655,X$1&" (8)",""))<lenb($Z655),8,IF(lenb(SUBSTITUTE($Z655,X$1&" (9)",""))<lenb($Z655),9,IF(lenb(SUBSTITUTE($Z655,X$1&" (10)",""))<lenb($Z655),10,IF(lenb(SUBSTITUTE($Z655,X$1,""))<lenb($Z655),"ERROR",IF($Z655=$Y$1,"-",0)))))))))))) -> 0 | Y655: =IF(Z655=Y$1,1,"-") -> - | Z655: Publicly available (1) | AA655: =ifs(U655="","",U655="-",0,U655="Erro",0,U655<>"",LEN(U655)-LEN(SUBSTITUTE(U655,CHAR(10),""))+1) -> 1 | AB655: =COUNTIFS(Links!B:B,"ICSE",Links!C:C,A655,Links!AD:AD,1) -> 0 | AC655: Yes | AD655: =ifs(AE655="None.","No",AE655="-","No",AND(AE655<>"None.",AE655<>"-"),"Yes") -> No | AE655: - | AF655: ---- | AG655: ---- | AH655: ---- | AI655: =IF(AH655="----",IF(AG655="----",IF(AF655="----","----",AF655),AF655&CHAR(10)&AG655),AF655&CHAR(10)&AG655&CHAR(10)&AH655) -> ---- | AJ655: =IFERROR( if(and(K655="Yes",AD655="No"),"Paper has link but no statement", if(and(K655="No",AD655="No"),"Paper has no link and no statement", if(and(K655="Yes",AD655="Yes"),"Paper has link and statement", if(and(K655="No",AD655="Yes"),"Paper has no link but has statement","")))),"") -> Paper has link but no statement | AK655: 45027 | AL655: Technical | AM655: ="[IP"&TEXT(A655,"0000")&"]" -> [IP0783]
A656: 784 | B656: Managing data constraints in database-backed web applications | C656: 2020 | D656: Yes | E656: Yes | F656: No | G656: Yes | H656: No | I656: No | J656: - | K656: Yes | L656: No | M656: Yes | N656: Yes | O656: No | P656: No | Q656: No | R656: No | S656: [12] 1 INTRODUCTION * | T656: https://hyperloop-rails.github.io/vibranium/ | U656: https://hyperloop-rails.github.io/vibranium/ | V656: =IF(lenb(SUBSTITUTE($Z656,V$1&" (1)",""))<lenb($Z656),1,IF(lenb(SUBSTITUTE($Z656,V$1&" (2)",""))<lenb($Z656),2,IF(lenb(SUBSTITUTE($Z656,V$1&" (3)",""))<lenb($Z656),3,IF(lenb(SUBSTITUTE($Z656,V$1&" (4)",""))<lenb($Z656),4,IF(lenb(SUBSTITUTE($Z656,V$1&" (5)",""))<lenb($Z656),5,IF(lenb(SUBSTITUTE($Z656,V$1&" (6)",""))<lenb($Z656),6,IF(lenb(SUBSTITUTE($Z656,V$1&" (7)",""))<lenb($Z656),1,IF(lenb(SUBSTITUTE($Z656,V$1&" (8)",""))<lenb($Z656),8,IF(lenb(SUBSTITUTE($Z656,V$1&" (9)",""))<lenb($Z656),9,IF(lenb(SUBSTITUTE($Z656,V$1&" (10)",""))<lenb($Z656),10,IF(lenb(SUBSTITUTE($Z656,V$1,""))<lenb($Z656),"ERROR",IF($Z656=$Y$1,"-",0)))))))))))) -> 1 | W656: =IF(lenb(SUBSTITUTE($Z656,W$1&" (1)",""))<lenb($Z656),1,IF(lenb(SUBSTITUTE($Z656,W$1&" (2)",""))<lenb($Z656),2,IF(lenb(SUBSTITUTE($Z656,W$1&" (3)",""))<lenb($Z656),3,IF(lenb(SUBSTITUTE($Z656,W$1&" (4)",""))<lenb($Z656),4,IF(lenb(SUBSTITUTE($Z656,W$1&" (5)",""))<lenb($Z656),5,IF(lenb(SUBSTITUTE($Z656,W$1&" (6)",""))<lenb($Z656),6,IF(lenb(SUBSTITUTE($Z656,W$1&" (7)",""))<lenb($Z656),1,IF(lenb(SUBSTITUTE($Z656,W$1&" (8)",""))<lenb($Z656),8,IF(lenb(SUBSTITUTE($Z656,W$1&" (9)",""))<lenb($Z656),9,IF(lenb(SUBSTITUTE($Z656,W$1&" (10)",""))<lenb($Z656),10,IF(lenb(SUBSTITUTE($Z656,W$1,""))<lenb($Z656),"ERROR",IF($Z656=$Y$1,"-",0)))))))))))) -> 0 | X656: =IF(lenb(SUBSTITUTE($Z656,X$1&" (1)",""))<lenb($Z656),1,IF(lenb(SUBSTITUTE($Z656,X$1&" (2)",""))<lenb($Z656),2,IF(lenb(SUBSTITUTE($Z656,X$1&" (3)",""))<lenb($Z656),3,IF(lenb(SUBSTITUTE($Z656,X$1&" (4)",""))<lenb($Z656),4,IF(lenb(SUBSTITUTE($Z656,X$1&" (5)",""))<lenb($Z656),5,IF(lenb(SUBSTITUTE($Z656,X$1&" (6)",""))<lenb($Z656),6,IF(lenb(SUBSTITUTE($Z656,X$1&" (7)",""))<lenb($Z656),1,IF(lenb(SUBSTITUTE($Z656,X$1&" (8)",""))<lenb($Z656),8,IF(lenb(SUBSTITUTE($Z656,X$1&" (9)",""))<lenb($Z656),9,IF(lenb(SUBSTITUTE($Z656,X$1&" (10)",""))<lenb($Z656),10,IF(lenb(SUBSTITUTE($Z656,X$1,""))<lenb($Z656),"ERROR",IF($Z656=$Y$1,"-",0)))))))))))) -> 0 | Y656: =IF(Z656=Y$1,1,"-") -> - | Z656: Publicly available (1) | AA656: =ifs(U656="","",U656="-",0,U656="Erro",0,U656<>"",LEN(U656)-LEN(SUBSTITUTE(U656,CHAR(10),""))+1) -> 1 | AB656: =COUNTIFS(Links!B:B,"ICSE",Links!C:C,A656,Links!AD:AD,1) -> 0 | AC656: No | AD656: =ifs(AE656="None.","No",AE656="-","No",AND(AE656<>"None.",AE656<>"-"),"Yes") -> No | AE656: - | AF656: ---- | AG656: ---- | AH656: ---- | AI656: =IF(AH656="----",IF(AG656="----",IF(AF656="----","----",AF656),AF656&CHAR(10)&AG656),AF656&CHAR(10)&AG656&CHAR(10)&AH656) -> ---- | AJ656: =IFERROR( if(and(K656="Yes",AD656="No"),"Paper has link but no statement", if(and(K656="No",AD656="No"),"Paper has no link and no statement", if(and(K656="Yes",AD656="Yes"),"Paper has link and statement", if(and(K656="No",AD656="Yes"),"Paper has no link but has statement","")))),"") -> Paper has link but no statement | AK656: 45027 | AL656: Technical | AM656: ="[IP"&TEXT(A656,"0000")&"]" -> [IP0784]
